# Insert data into Passwords table
passwords_data = [
    ("Email Account", "user1@example.com", "password123", "https://mail.example.com", None, None, now(), None),
    ("Bank Account", "bankuser", "securepass456", "https://bank.example.com", "Primary bank", None, now(), now()),
    ("Social Media", "socialguy", "myp@ssword", None, None, None, now(), None),
    ("Old Forum", "forumuser", "forum1234", "https://oldforum.com", "Rarely used", ten_years_ago(), now(), None)
]

cursor.executemany("""
INSERT INTO Passwords (Name, LoginID, Password, URL, Notes, DeletedDate, CreationDate, ModificationDate)
VALUES (%s, %s, %s, %s, %s, %s, %s, %s)
""", passwords_data)

# Insert data into Certificates table
certificates_data = [
    ("Web Server Cert", "web01", "CERTDATA1", None, None, now(), None),
    ("API Server Cert", "api01", "CERTDATA2", "Used for internal API", None, now(), now()),
    ("Backup Server Cert", "backup01", "CERTDATA3", None, None, now(), None),
    ("Legacy Server Cert", "legacy01", "CERTDATA4", None, ten_years_ago(), now(), None)
]

cursor.executemany("""
INSERT INTO Certificates (Name, ServerName, Certificate, Notes, DeletedDate, CreationDate, ModificationDate)
VALUES (%s, %s, %s, %s, %s, %s, %s)
""", certificates_data)



(.venv2) PS C:\Users\Administrator\Documents\apiPython> & C:/Users/Administrator/Documents/apiPython/.venv2/Scripts/python.exe c:/Users/Administrator/Documents/apiPython/Lab/lab.py
Traceback (most recent call last):
  File "C:\Users\Administrator\Documents\apiPython\.venv2\Lib\site-packages\mysql\connector\connection_cext.py", line 772, in cmd_query
    self._cmysql.query(
    ~~~~~~~~~~~~~~~~~~^
        query,
        ^^^^^^
    ...<3 lines>...
        query_attrs=self.query_attrs,
        ^^^^^^^^^^^^^^^^^^^^^^^^^^^^^
    )
    ^
_mysql_connector.MySQLInterfaceError: You have an error in your SQL syntax; check the manual that corresponds to your MySQL server version for the right syntax to use near 'Notes TEXT,
        DeletedDate DATETIME,
        CreationDate DATETIME NOT NULL' at line 7

The above exception was the direct cause of the following exception:

Traceback (most recent call last):
  File "c:\Users\Administrator\Documents\apiPython\Lab\lab.py", line 27, in <module>
    cursor.execute("""
    ~~~~~~~~~~~~~~^^^^
        CREATE TABLE IF NOT EXISTS Passwords (
        ^^^^^^^^^^^^^^^^^^^^^^^^^^^^^^^^^^^^^^
    ...<9 lines>...
        )
        ^
                   """)
                   ^^^^
  File "C:\Users\Administrator\Documents\apiPython\.venv2\Lib\site-packages\mysql\connector\cursor_cext.py", line 353, in execute
    self._connection.cmd_query(
    ~~~~~~~~~~~~~~~~~~~~~~~~~~^
        self._stmt_partition["mappable_stmt"],
        ^^^^^^^^^^^^^^^^^^^^^^^^^^^^^^^^^^^^^^
    ...<2 lines>...
        raw_as_string=self._raw_as_string,
        ^^^^^^^^^^^^^^^^^^^^^^^^^^^^^^^^^^
    )
    ^
  File "C:\Users\Administrator\Documents\apiPython\.venv2\Lib\site-packages\mysql\connector\opentelemetry\context_propagation.py", line 97, in wrapper
    return method(cnx, *args, **kwargs)
  File "C:\Users\Administrator\Documents\apiPython\.venv2\Lib\site-packages\mysql\connector\connection_cext.py", line 781, in cmd_query
    raise get_mysql_exception(
        err.errno, msg=err.msg, sqlstate=err.sqlstate
    ) from err
mysql.connector.errors.ProgrammingError: 1064 (42000): You have an error in your SQL syntax; check the manual that corresponds to your MySQL server version for the right syntax to use near 'Notes TEXT,
        DeletedDate DATETIME,
        CreationDate DATETIME NOT NULL' at line 7
(.venv2) PS C:\Users\Administrator\Documents\apiPython> 
